Organization: remilab
Project: byungkwan
Displayed last 30 lines of #369367246094.
[01:00:04.666737] workload awaiting to start
[01:00:04.666837] Workload status changed to pending
[01:00:09.585023] Event Reason: FailedScheduling, Event Note: 0/13 nodes are available: 1 Insufficient nvidia.com/gpu, 3 node(s) had untolerated taint {node.kubernetes.io/unreachable: }, 9 node(s) didn't match Pod's node affinity/selector. preemption: 0/13 nodes are available: 1 No preemption victims found for incoming pod, 12 Preemption is not helpful for scheduling.
[01:00:09.585023] Workload is in queue for scheduling. Please wait...
[01:05:30.033067] Event Reason: FailedScheduling, Event Note: 0/13 nodes are available: 1 Insufficient nvidia.com/gpu, 3 node(s) had untolerated taint {node.kubernetes.io/unreachable: }, 9 node(s) didn't match Pod's node affinity/selector. preemption: 0/13 nodes are available: 1 No preemption victims found for incoming pod, 12 Preemption is not helpful for scheduling.
[01:05:30.033067] Workload is in queue for scheduling. Please wait...
[01:10:30.040600] Event Reason: FailedScheduling, Event Note: 0/13 nodes are available: 1 Insufficient nvidia.com/gpu, 3 node(s) had untolerated taint {node.kubernetes.io/unreachable: }, 9 node(s) didn't match Pod's node affinity/selector. preemption: 0/13 nodes are available: 1 No preemption victims found for incoming pod, 12 Preemption is not helpful for scheduling.
[01:10:30.040600] Workload is in queue for scheduling. Please wait...
[01:28:30.064566] Event Reason: FailedScheduling, Event Note: 0/13 nodes are available: 1 Insufficient nvidia.com/gpu, 3 node(s) had untolerated taint {node.kubernetes.io/unreachable: }, 9 node(s) didn't match Pod's node affinity/selector. preemption: 0/13 nodes are available: 1 No preemption victims found for incoming pod, 12 Preemption is not helpful for scheduling.
[01:28:30.064566] Workload is in queue for scheduling. Please wait...
[01:58:30.107520] Event Reason: FailedScheduling, Event Note: 0/13 nodes are available: 1 Insufficient nvidia.com/gpu, 3 node(s) had untolerated taint {node.kubernetes.io/unreachable: }, 9 node(s) didn't match Pod's node affinity/selector. preemption: 0/13 nodes are available: 1 No preemption victims found for incoming pod, 12 Preemption is not helpful for scheduling.
[01:58:30.107520] Workload is in queue for scheduling. Please wait...
[02:28:30.141227] Event Reason: FailedScheduling, Event Note: 0/13 nodes are available: 1 Insufficient nvidia.com/gpu, 3 node(s) had untolerated taint {node.kubernetes.io/unreachable: }, 9 node(s) didn't match Pod's node affinity/selector. preemption: 0/13 nodes are available: 1 No preemption victims found for incoming pod, 12 Preemption is not helpful for scheduling.
[02:28:30.141227] Workload is in queue for scheduling. Please wait...
[02:58:30.171978] Event Reason: FailedScheduling, Event Note: 0/13 nodes are available: 1 Insufficient nvidia.com/gpu, 3 node(s) had untolerated taint {node.kubernetes.io/unreachable: }, 9 node(s) didn't match Pod's node affinity/selector. preemption: 0/13 nodes are available: 1 No preemption victims found for incoming pod, 12 Preemption is not helpful for scheduling.
[02:58:30.171978] Workload is in queue for scheduling. Please wait...
[03:28:30.206378] Event Reason: FailedScheduling, Event Note: 0/13 nodes are available: 1 Insufficient nvidia.com/gpu, 3 node(s) had untolerated taint {node.kubernetes.io/unreachable: }, 9 node(s) didn't match Pod's node affinity/selector. preemption: 0/13 nodes are available: 1 No preemption victims found for incoming pod, 12 Preemption is not helpful for scheduling.
[03:28:30.206378] Workload is in queue for scheduling. Please wait...
[03:58:30.242474] Event Reason: FailedScheduling, Event Note: 0/13 nodes are available: 1 Insufficient nvidia.com/gpu, 3 node(s) had untolerated taint {node.kubernetes.io/unreachable: }, 9 node(s) didn't match Pod's node affinity/selector. preemption: 0/13 nodes are available: 1 No preemption victims found for incoming pod, 12 Preemption is not helpful for scheduling.
[03:58:30.242474] Workload is in queue for scheduling. Please wait...
[04:28:30.277466] Event Reason: FailedScheduling, Event Note: 0/13 nodes are available: 1 Insufficient nvidia.com/gpu, 3 node(s) had untolerated taint {node.kubernetes.io/unreachable: }, 9 node(s) didn't match Pod's node affinity/selector. preemption: 0/13 nodes are available: 1 No preemption victims found for incoming pod, 12 Preemption is not helpful for scheduling.
[04:28:30.277466] Workload is in queue for scheduling. Please wait...
[04:58:30.315018] Event Reason: FailedScheduling, Event Note: 0/13 nodes are available: 1 Insufficient nvidia.com/gpu, 3 node(s) had untolerated taint {node.kubernetes.io/unreachable: }, 9 node(s) didn't match Pod's node affinity/selector. preemption: 0/13 nodes are available: 1 No preemption victims found for incoming pod, 12 Preemption is not helpful for scheduling.
[04:58:30.315018] Workload is in queue for scheduling. Please wait...
[05:28:30.355957] Event Reason: FailedScheduling, Event Note: 0/13 nodes are available: 1 Insufficient nvidia.com/gpu, 3 node(s) had untolerated taint {node.kubernetes.io/unreachable: }, 9 node(s) didn't match Pod's node affinity/selector. preemption: 0/13 nodes are available: 1 No preemption victims found for incoming pod, 12 Preemption is not helpful for scheduling.
[05:28:30.355957] Workload is in queue for scheduling. Please wait...
[05:58:30.395824] Event Reason: FailedScheduling, Event Note: 0/13 nodes are available: 1 Insufficient nvidia.com/gpu, 3 node(s) had untolerated taint {node.kubernetes.io/unreachable: }, 9 node(s) didn't match Pod's node affinity/selector. preemption: 0/13 nodes are available: 1 No preemption victims found for incoming pod, 12 Preemption is not helpful for scheduling.
[05:58:30.395824] Workload is in queue for scheduling. Please wait...
[06:28:30.437229] Event Reason: FailedScheduling, Event Note: 0/13 nodes are available: 1 Insufficient nvidia.com/gpu, 3 node(s) had untolerated taint {node.kubernetes.io/unreachable: }, 9 node(s) didn't match Pod's node affinity/selector. preemption: 0/13 nodes are available: 1 No preemption victims found for incoming pod, 12 Preemption is not helpful for scheduling.
[06:28:30.437229] Workload is in queue for scheduling. Please wait...
